<?xml version="1.0" ?>
<!-- =================================================================================== -->
<!-- |    This document was autogenerated by xacro from ddrive.urdf.xacro              | -->
<!-- |    EDITING THIS FILE BY HAND IS NOT RECOMMENDED                                 | -->
<!-- =================================================================================== -->
<robot name="ddrive">
  <gazebo>
    <plugin filename="libgazebo_ros_diff_drive.so" name="differential_drive_controller">
      <rosDebugLevel>na</rosDebugLevel>
      <alwaysOn>true</alwaysOn>
      <updateRate>100</updateRate>
      <leftJoint>left_wheel_hinge</leftJoint>
      <rightJoint>right_wheel_hinge</rightJoint>
      <wheelSeparation>0.35</wheelSeparation>
      <wheelDiameter>0.16</wheelDiameter>
      <wheelTorque>20</wheelTorque>
      <commandTopic>cmd_vel</commandTopic>
      <odometryTopic>odom</odometryTopic>
      <odometryFrame>odom</odometryFrame>
      <robotBaseFrame>base_link</robotBaseFrame>
      <publishWheelTF>false</publishWheelTF>
      <publishOdomTF>true</publishOdomTF>
      <publishWheelJointState>true</publishWheelJointState>
      <wheelAcceleration>false</wheelAcceleration>
      <odometrySource>world</odometrySource>
      <publishTf>1</publishTf>
    </plugin>
  </gazebo>
  <gazebo reference="chassis">
    <material>Gazebo/Blue</material>
  </gazebo>
  <gazebo reference="left_wheel">
    <material>Gazebo/Yellow</material>
    <mu1>999</mu1>
    <mu2>999</mu2>
    <kp>500000.0</kp>
    <kd>10.0</kd>
    <minDepth>0.001</minDepth>
    <maxVel>0.1</maxVel>
    <fdir1>1 0 0</fdir1>
  </gazebo>
  <gazebo reference="right_wheel">
    <material>Gazebo/Yellow</material>
    <mu1>999</mu1>
    <mu2>999</mu2>
    <kp>500000.0</kp>
    <kd>10.0</kd>
    <minDepth>0.001</minDepth>
    <maxVel>0.1</maxVel>
    <fdir1>1 0 0</fdir1>
  </gazebo>
  <link name="base_link"/>
  <joint name="base_link_joint" type="fixed">
    <origin rpy="0 0 0" xyz="0 0 0"/>
    <parent link="base_link"/>
    <child link="chassis"/>
  </joint>
  <link name="chassis">
    <pose>0 0 0.0 0 0 0</pose>
    <inertial>
      <mass value="2"/>
      <origin rpy=" 0 0 0" xyz="0.0 0 0.0"/>
      <inertia ixx="0.0174" ixy="0" ixz="0" iyy="0.04406666666666667" iyz="0" izz="0.05666666666666666"/>
    </inertial>
    <collision name="chassis_collision">
      <origin rpy=" 0 0 0" xyz="0 0 0.0"/>
      <geometry>
        <box size="0.5 0.3 0.12"/>
      </geometry>
    </collision>
    <visual name="chassis_visual">
      <origin rpy=" 0 0 0" xyz="0 0 0.0"/>
      <geometry>
        <box size="0.5 0.3 0.12"/>
      </geometry>
    </visual>
  </link>
  <link name="bottom_caster">
    <inertial>
      <mass value="0"/>
      <origin rpy=" 0 0 0" xyz="0 0 0"/>
      <inertia ixx="0.0" ixy="0" ixz="0" iyy="0.0" iyz="0" izz="0.0"/>
    </inertial>
    <collision name="bottom_caster_collision">
      <origin rpy=" 0 0 0" xyz="0 0 0"/>
      <geometry>
        <sphere radius="0.03"/>
      </geometry>
    </collision>
    <visual name="bottom_caster_visual">
      <origin rpy=" 0 0 0" xyz="0 0 0"/>
      <geometry>
        <sphere radius="0.03"/>
      </geometry>
    </visual>
  </link>
  <link name="top_caster">
    <inertial>
      <mass value="0.0"/>
      <origin rpy=" 0 0 0" xyz="0 0 0"/>
      <inertia ixx="0.0" ixy="0" ixz="0" iyy="0.0" iyz="0" izz="0.0"/>
    </inertial>
    <collision name="top_caster_collision">
      <origin rpy=" 0 0 0" xyz="0 0 0"/>
      <geometry>
        <sphere radius="0.03"/>
      </geometry>
    </collision>
    <visual name="top_caster_visual">
      <origin rpy=" 0 0 0" xyz="0 0 0"/>
      <geometry>
        <sphere radius="0.03"/>
      </geometry>
    </visual>
  </link>
  <link name="left_wheel">
    <inertial>
      <mass value="4"/>
      <origin rpy=" 0 1.5707 1.5707" xyz="0.0 0 0.0"/>
      <inertia ixx="0.010833333333333335" ixy="0" ixz="0" iyy="0.010833333333333335" iyz="0" izz="0.003333333333333334"/>
    </inertial>
    <collision name="left_wheel_collision">
      <origin rpy=" 0 1.5707 1.5707" xyz="0 0 0.0"/>
      <geometry>
        <cylinder length="0.05" radius="0.1"/>
      </geometry>
    </collision>
    <visual name="left_wheel_visual">
      <origin rpy=" 0 1.5707 1.5707" xyz="0 0 0.0"/>
      <geometry>
        <cylinder length="0.05" radius="0.1"/>
      </geometry>
    </visual>
  </link>
  <link name="right_wheel">
    <inertial>
      <mass value="4"/>
      <origin rpy=" 0 1.5707 1.5707" xyz="0.0 0 0.0"/>
      <inertia ixx="0.010833333333333335" ixy="0" ixz="0" iyy="0.010833333333333335" iyz="0" izz="0.003333333333333334"/>
    </inertial>
    <collision name="right_wheel_collision">
      <origin rpy=" 0 1.5707 1.5707" xyz="0 0 0.0"/>
      <geometry>
        <cylinder length="0.05" radius="0.1"/>
      </geometry>
    </collision>
    <visual name="right_wheel_visual">
      <origin rpy=" 0 1.5707 1.5707" xyz="0 0 0.0"/>
      <geometry>
        <cylinder length="0.05" radius="0.1"/>
      </geometry>
    </visual>
  </link>
   --&gt;

  
  <joint name="left_wheel_hinge" type="continuous">
    <origin rpy="0 0 0" xyz="-0.14 0.18 0"/>
    <child link="left_wheel"/>
    <parent link="chassis"/>
    <axis rpy="0 0 0" xyz="0 1 0"/>
  </joint>
  <joint name="right_wheel_hinge" type="continuous">
    <origin rpy="0 0 0" xyz="-0.14 -0.18 0"/>
    <child link="right_wheel"/>
    <parent link="chassis"/>
    <axis rpy="0 0 0" xyz="0 1 0"/>
  </joint>
  <joint name="bottom_caster_joint" type="fixed">
    <origin rpy="0 0 0" xyz="0.20 0 -0.05"/>
    <child link="bottom_caster"/>
    <parent link="chassis"/>
    <axis rpy="0 0 0" xyz="1 0 0"/>
  </joint>
  <joint name="top_caster_joint" type="fixed">
    <origin rpy="0 0 0" xyz="0.20 0 0.05"/>
    <child link="top_caster"/>
    <parent link="chassis"/>
    <axis rpy="0 0 0" xyz="1 0 0"/>
  </joint>
</robot>

