<?xml version="1.0" ?>
<!-- =================================================================================== -->
<!-- |    This document was autogenerated by xacro from ddrive.urdf.xacro              | -->
<!-- |    EDITING THIS FILE BY HAND IS NOT RECOMMENDED                                 | -->
<!-- =================================================================================== -->
<robot name="ddrive">
  <plugin filename="libgazebo_ros_diff_drive.so" name="differential_drive_controller">
    <legacyMode>false</legacyMode>
    <alwaysOn>true</alwaysOn>
    <updateRate>10</updateRate>
    <leftJoint>left_wheel_hinge</leftJoint>
    <rightJoint>right_wheel_hinge</rightJoint>
    <wheelSeparation>0.4</wheelSeparation>
    <wheelDiameter>0.2</wheelDiameter>
    <torque>10</torque>
    <commandTopic>cmd_vel</commandTopic>
    <odometryTopic>odom</odometryTopic>
    <odometryFrame>odom</odometryFrame>
    <robotBaseFrame>body_footprint</robotBaseFrame>
    <publishWheelTF>false</publishWheelTF>
    <publishWheelJointState>false</publishWheelJointState>
    <rosDebugLevel>na</rosDebugLevel>
    <wheelAcceleration>0</wheelAcceleration>
    <wheelTorque>5</wheelTorque>
    <odometrySource>world</odometrySource>
    <publishTf>1</publishTf>
    <publishOdomTF>true</publishOdomTF>
  </plugin>
  <link name="body_footprint"/>
  <joint name="body_footprint_joint" type="fixed">
    <origin rpy="0 0 0" xyz="0 0 0"/>
    <parent link="body_footprint"/>
    <child link="chassis"/>
  </joint>
  <link name="chassis">
    <pose>0 0 0 0 0 0</pose>
    <inertial>
      <mass value="10.0"/>
      <origin rpy=" 0 0 0" xyz="0.0 0 0.2"/>
      <inertia ixx="0.1" ixy="0" ixz="0" iyy="0.1" iyz="0" izz="0.1"/>
    </inertial>
    <collision name="chassis_collision">
      <origin rpy=" 0 0 0" xyz="0 0 0"/>
      <geometry>
        <box size="0.5 0.3 0.12"/>
      </geometry>
    </collision>
    <visual name="chassis_visual">
      <origin rpy=" 0 0 0" xyz="0 0 0"/>
      <geometry>
        <box size="0.5 0.3 0.12"/>
      </geometry>
    </visual>
    <collision name="bottom_caster_collision">
      <origin rpy=" 0 0 0" xyz="-0.20 0 -0.05"/>
      <geometry>
        <sphere radius="0.03"/>
      </geometry>
    </collision>
    <visual name="bottom_caster_visual">
      <origin rpy=" 0 0 0" xyz="-0.20 0 -0.05"/>
      <geometry>
        <sphere radius="0.03"/>
      </geometry>
    </visual>
    <collision name="top_caster_collision">
      <origin rpy=" 0 0 0" xyz="-0.20 0 0.05"/>
      <geometry>
        <sphere radius="0.03"/>
      </geometry>
    </collision>
    <visual name="top_caster_visual">
      <origin rpy=" 0 0 0" xyz="-0.20 0 0.05"/>
      <geometry>
        <sphere radius="0.03"/>
      </geometry>
    </visual>
  </link>
  <link name="left_wheel">
    <inertial>
      <mass value="5.0"/>
      <origin rpy=" 0 1.5707 1.5707" xyz="0.0 0 0"/>
      <inertia ixx="0.1" ixy="0" ixz="0" iyy="0.1" iyz="0" izz="0.1"/>
    </inertial>
    <collision name="left_wheel_collision">
      <origin rpy=" 0 1.5707 1.5707" xyz="0 0 0"/>
      <geometry>
        <cylinder length="0.05" radius="0.08"/>
      </geometry>
    </collision>
    <visual name="left_wheel_visual">
      <origin rpy=" 0 1.5707 1.5707" xyz="0 0 0"/>
      <geometry>
        <cylinder length="0.05" radius="0.08"/>
      </geometry>
    </visual>
  </link>
  <link name="right_wheel">
    <inertial>
      <mass value="5.0"/>
      <origin rpy=" 0 1.5707 1.5707" xyz="0.0 0 0"/>
      <inertia ixx="0.1" ixy="0" ixz="0" iyy="0.1" iyz="0" izz="0.1"/>
    </inertial>
    <collision name="right_wheel_collision">
      <origin rpy=" 0 1.5707 1.5707" xyz="0 0 0"/>
      <geometry>
        <cylinder length="0.05" radius="0.08"/>
      </geometry>
    </collision>
    <visual name="right_wheel_visual">
      <origin rpy=" 0 1.5707 1.5707" xyz="0 0 0"/>
      <geometry>
        <cylinder length="0.05" radius="0.08"/>
      </geometry>
    </visual>
  </link>
  <joint name="left_wheel_hinge" type="continuous">
    <origin rpy="0 0 0" xyz="0.14 0.18 0"/>
    <child link="left_wheel"/>
    <parent link="chassis"/>
    <axis rpy="0 0 0" xyz="0 1 0"/>
    <limit effort="10000" velocity="1000"/>
    <dynamics damping="1.0" friction="1.0"/>
  </joint>
  <joint name="right_wheel_hinge" type="continuous">
    <origin rpy="0 0 0" xyz="0.14 -0.18 0"/>
    <child link="right_wheel"/>
    <parent link="chassis"/>
    <axis rpy="0 0 0" xyz="0 1 0"/>
    <limit effort="10000" velocity="1000"/>
    <dynamics damping="1.0" friction="1.0"/>
  </joint>
  <gazebo reference="chassis">
    <material>Gazebo/Blue</material>
  </gazebo>
  <gazebo reference="left_wheel">
    <material>Gazebo/Yellow</material>
  </gazebo>
  <gazebo reference="right_wheel">
    <material>Gazebo/Yellow</material>
  </gazebo>
</robot>

